Workbook

Sheet REMOTAS
C1: Milhão Ingredients Unidade - Rio Verde
C2: ATUALIZAÇÃO 18/03/2025
G3: RESPONSAVEL TÉCNICO- Tallison Barros;
C4: DEVICES
C6: CPU CONTROLOGIX 1756-L73
C8: 1756-EN2TR ETH01 192.100.3.1
C10: =#REF! -> #REF!
C11: =#REF! -> #REF!
C12: =#REF! -> #REF!
C13: =#REF! -> #REF!
C14: =#REF! -> #REF!
C15: =#REF! -> #REF!
C17: =#REF! -> #REF!
C18: =#REF! -> #REF!
C19: =#REF! -> #REF!
C20: =#REF! -> #REF!
C21: =#REF! -> #REF!
C22: =#REF! -> #REF!
... C29: =#REF! -> #REF!
C31: =RemCCM3!C6 -> 1734-AENTR/c RemCCM3 192.100.3.50
C32: =RemCCM3!C7 -> SLOT 01 1734-IB8/C - 08 DI
C33: =RemCCM3!C17 -> SLOT 02 1734-IB8/C - 08 DI
C34: =RemCCM3!C27 -> SLOT 03 1734-IB8/C - 08 DI
C35: =RemCCM3!C37 -> SLOT 04 1734-OB8/C - 08 DO
C36: =RemCCM3!C47 -> SLOT 05 1734-OB8/C - 08 DO
C37: =RemCCM3!C57 -> SLOT 06 1734-OB8/C - 08 DO
C38: =RemCCM3!C67 -> SLOT 07 1734-IB8/C - 08 DI
C39: =RemCCM3!C77 -> SLOT 08 1734-OB8/C - 08 DO
C40: =RemCCM3!C87 -> SLOT 09 1734-OB8/C - 08 DO
C42: =#REF! -> #REF!
C43: =#REF! -> #REF!
C44: =#REF! -> #REF!
C45: =#REF! -> #REF!
C46: =#REF! -> #REF!
C47: =#REF! -> #REF!
C48: =#REF! -> #REF!
C49: =#REF! -> #REF!
C50: =#REF! -> #REF!
C51: =#REF! -> #REF!
C52: =#REF! -> #REF!
...

Sheet RemCCM3
C1: Milhão Ingredients Unidade - Rio Verde
C2: CPU CONTROLOGIX 1756-L73 192.100.3.1
C3: LISTA DE IO
G4: RESPONSAVEL TÉCNICO- Tallison Barros;
C6: 1734-AENTR/c RemCCM3 192.100.3.50
C7: SLOT 01 1734-IB8/C - 08 DI
C8: IO | D8: Local | E8: Min | F8: Max | G8: TAG 's | H8: DESCRIÇÃO
C9: DI.0 | E9: 0 | F9: 1
C10: DI.1 | E10: 0 | F10: 1
C11: DI.2 | E11: 0 | F11: 1
C12: DI.3 | E12: 0 | F12: 1
C13: DI.4 | E13: 0 | F13: 1
C14: DI.5 | E14: 0 | F14: 1
C15: DI.6 | E15: 0 | F15: 1 | G15: LIMVR06.FB
C16: DI.7 | E16: 0 | F16: 1
C17: SLOT 02 1734-IB8/C - 08 DI
C18: IO | D18: Local | E18: Min | F18: Max | G18: TAG 's | H18: DESCRIÇÃO
C19: DI.0 | E19: 0 | F19: 1
C20: DI.1 | E20: 0 | F20: 1
C21: DI.2 | E21: 0 | F21: 1
C22: DI.3 | E22: 0 | F22: 1
C23: DI.4 | E23: 0 | F23: 1
C24: DI.5 | E24: 0 | F24: 1
C25: DI.6 | E25: 0 | F25: 1
C26: DI.7 | E26: 0 | F26: 1
C27: SLOT 03 1734-IB8/C - 08 DI
C28: IO | D28: Local | E28: Min | F28: Max | G28: TAG 's | H28: DESCRIÇÃO
C29: DI.0 | E29: 0 | F29: 1
C30: DI.1 | E30: 0 | F30: 1
C31: DI.2 | E31: 0 | F31: 1
C32: DI.3 | E32: 0 | F32: 1
C33: DI.4 | E33: 0 | F33: 1
C34: DI.5 | E34: 0 | F34: 1 | G34: LIMVT06.FB
C35: DI.6 | E35: 0 | F35: 1
C36: DI.7 | E36: 0 | F36: 1
C37: SLOT 04 1734-OB8/C - 08 DO
C38: IO | D38: Local | E38: Min | F38: Max | G38: TAG 's | H38: DESCRIÇÃO
C39: DO.0 | E39: 0 | F39: 1
C40: DO.1 | E40: 0 | F40: 1
C41: DO.2 | E41: 0 | F41: 1
...

Sheet Rem7
C1: Milhão Ingredients Unidade - Rio Verde
C2: CPU CONTROLOGIX 1756-L73 192.100.3.1
C3: LISTA DE IO
G4: RESPONSAVEL TÉCNICO- Tallison Barros;
C6: 1734-AENTR/c REM-7 192.100.3.166 7º PISO ENSAQUE
C7: SLOT 01 1734-IB8/C - 08 DI
C8: IO | D8: Local | E8: Min | F8: Max | G8: TAG 's | H8: DESCRIÇÃO
C9: DI.0 | E9: 0 | F9: 1
C10: DI.1 | E10: 0 | F10: 1
C11: DI.2 | E11: 0 | F11: 1
C12: DI.3 | E12: 0 | F12: 1
C13: DI.4 | E13: 0 | F13: 1
C14: DI.5 | E14: 0 | F14: 1
C15: DI.6 | E15: 0 | F15: 1
C16: DI.7 | E16: 0 | F16: 1
C17: SLOT 02 1734-IB8/C - 08 DI
C18: IO | D18: Local | E18: Min | F18: Max | G18: TAG 's | H18: DESCRIÇÃO
C19: DI.0 | E19: 0 | F19: 1
C20: DI.1 | E20: 0 | F20: 1
C21: DI.2 | E21: 0 | F21: 1
C22: DI.3 | E22: 0 | F22: 1
C23: DI.4 | E23: 0 | F23: 1
C24: DI.5 | E24: 0 | F24: 1
C25: DI.6 | E25: 0 | F25: 1
C26: DI.7 | E26: 0 | F26: 1
C27: SLOT 03 1734-IB8/C - 08 DI
C28: IO | D28: Local | E28: Min | F28: Max | G28: TAG 's | H28: DESCRIÇÃO
C29: DI.0 | E29: 0 | F29: 1
C30: DI.1 | E30: 0 | F30: 1
C31: DI.2 | E31: 0 | F31: 1
C32: DI.3 | E32: 0 | F32: 1
C33: DI.4 | E33: 0 | F33: 1
C34: DI.5 | E34: 0 | F34: 1
C35: DI.6 | E35: 0 | F35: 1
C36: DI.7 | E36: 0 | F36: 1
C37: SLOT 04 1734-IB8/C - 08 DI
C38: IO | D38: Local | E38: Min | F38: Max | G38: TAG 's | H38: DESCRIÇÃO
C39: DI.0 | E39: 0 | F39: 1
C40: DI.1 | E40: 0 | F40: 1
C41: DI.2 | E41: 0 | F41: 1
...
