Workbook

Sheet DEVICES
C1: Milhão Ingredients Unidade - Rio Verde
G3: RESPONSAVEL TÉCNICO: Tallison Barros;
C4: DEVICES
C6: CPU CONTROLOGIX 1756-L73
C8: 1756-EN2TR ETH01 192.100.3.1
C10: =RemCCM1!C6 -> 1734-AENTR/c RemCCM1 192.100.3.2
C11: =RemCCM1!C7 -> SLOT 01 1734-IB8/C : 08 DI
C12: =RemCCM1!C17 -> SLOT 02 1734-OB8/C : 08 DO
C13: =RemCCM1!C27 -> SLOT 03 1734-IE8C/C : 08 AI
C14: =RemCCM1!C37 -> SLOT 04 1734-IE8C/C : 08 AI
C15: =RemCCM1!C47 -> SLOT 05 1734-IE8C/C : 08 AI
C17: =RemCCM2!C6 -> 1734-AENTR/c RemCCM2 192.100.3.31
C18: =RemCCM2!C7 -> SLOT 01 1734-IB8/C : 08 DI
C19: =RemCCM2!C17 -> SLOT 02 1734-IB8/C : 08 DI
C20: =RemCCM2!C27 -> SLOT 03 1734-IB8/C : 08 DI
C21: =RemCCM2!C37 -> SLOT 04 1734-IB8/C : 08 DI
C22: =RemCCM2!C47 -> SLOT 05 1734-IB8/C : 08 DI
C23: =RemCCM2!C57 -> SLOT 06 1734-OB8/C : 08 DO
C24: =RemCCM2!C67 -> SLOT 07 1734-OB8/C : 08 DO
C25: =RemCCM2!C77 -> SLOT 08 1734-OB8/C : 08 DO
C26: =RemCCM2!C87 -> SLOT 09 1734-OB8/C : 08 DO
C27: =RemCCM2!C97 -> SLOT 10 1734-OB8/C : 08 DO
C28: =RemCCM2!C107 -> SLOT 11 1734-IB8/C : 08 DI
C29: =RemCCM2!C117 -> SLOT 12 1734-OB8/C : 08 DO
C31: =RemCCM3!C6 -> 1734-AENTR/c RemCCM3 192.100.3.50
C32: =RemCCM3!C7 -> SLOT 01 1734-IB8/C : 08 DI
C33: =RemCCM3!C17 -> SLOT 02 1734-IB8/C : 08 DI
C34: =RemCCM3!C27 -> SLOT 03 1734-IB8/C : 08 DI
C35: =RemCCM3!C37 -> SLOT 04 1734-OB8/C : 08 DO
C36: =RemCCM3!C47 -> SLOT 05 1734-OB8/C : 08 DO
C37: =RemCCM3!C57 -> SLOT 06 1734-OB8/C : 08 DO
C38: =RemCCM3!C67 -> SLOT 07 1734-IB8/C : 08 DI
C39: =RemCCM3!C77 -> SLOT 08 1734-OB8/C : 08 DO
C40: =RemCCM3!C87 -> SLOT 09 1734-OB8/C : 08 DO
C42: =RemCCM4!C6 -> 1734-AENTR/c RemCCM4 192.100.3.86
C43: =RemCCM4!C7 -> SLOT 01 1734-IB8/C : 08 DI
C44: =RemCCM4!C17 -> SLOT 02 1734-IB8/C : 08 DI
C45: =RemCCM4!C27 -> SLOT 03 1734-IB8/C : 08 DI
C46: =RemCCM4!C37 -> SLOT 04 1734-IB8/C : 08 DI
C47: =RemCCM4!C47 -> SLOT 05 1734-IB8/C : 08 DI
...

Sheet RemCCM1
C1: Milhão Ingredients Unidade - Rio Verde
C2: CPU CONTROLOGIX 1756-L73 192.100.3.1
C3: LISTA DE IO
G4: RESPONSAVEL TÉCNICO: Tallison Barros;
C6: 1734-AENTR/c RemCCM1 192.100.3.2
C7: SLOT 01 1734-IB8/C : 08 DI
C8: IO | D8: Local | E8: Min | F8: Max | G8: TAG 's | H8: DESCRIÇÃO
C9: DI.0 | E9: 0 | F9: 1 | G9: M41BC4A.fb | H9: BANCO DE CILINDROS - Motoror Rolo de Moagem A
C10: DI.1 | E10: 0 | F10: 1 | G10: M41BC4B.fb | H10: BANCO DE CILINDROS - Motoror Rolo de Moagem B
C11: DI.2 | E11: 0 | F11: 1 | G11: M41BC5A.fb | H11: BANCO DE CILINDROS - Motoror Rolo de Moagem A
C12: DI.3 | E12: 0 | F12: 1 | G12: M41BC5B.fb | H12: BANCO DE CILINDROS - Motoror Rolo de Moagem B
C13: DI.4 | E13: 0 | F13: 1 | G13: M41BC10A.fb | H13: BANCO DE CILINDROS - Motoror Rolo de Moagem A
C14: DI.5 | E14: 0 | F14: 1 | G14: M41BC10B.fb | H14: BANCO DE CILINDROS - Motoror Rolo de Moagem B
C15: DI.6 | E15: 0 | F15: 1 | G15: EMERGENCIA_CCM1.ZsCampo | H15: EMERGENCIA_CCM1
C16: DI.7
C17: SLOT 02 1734-OB8/C : 08 DO
C18: IO | D18: Local | E18: Min | F18: Max | G18: TAG 's | H18: DESCRIÇÃO
C19: DO.0 | E19: 0 | F19: 1 | G19: M41BC4A.saida | H19: BANCO DE CILINDROS - Motoror Rolo de Moagem A
C20: DO.1 | E20: 0 | F20: 1 | G20: M41BC4B.saida | H20: BANCO DE CILINDROS - Motoror Rolo de Moagem B
C21: DO.2 | E21: 0 | F21: 1 | G21: M41BC5A.saida | H21: BANCO DE CILINDROS - Motoror Rolo de Moagem A
C22: DO.3 | E22: 0 | F22: 1 | G22: M41BC5B.saida | H22: BANCO DE CILINDROS - Motoror Rolo de Moagem B
C23: DO.4 | E23: 0 | F23: 1 | G23: M41BC10A.saida | H23: BANCO DE CILINDROS - Motoror Rolo de Moagem A
C24: DO.5 | E24: 0 | F24: 1 | G24: M41BC10B.saida | H24: BANCO DE CILINDROS - Motoror Rolo de Moagem B
C25: DO.6
C26: DO.7
C27: SLOT 03 1734-IE8C/C : 08 AI
C28: IO | D28: Local | E28: Min | F28: Max | G28: TAG 's | H28: DESCRIÇÃO
C29: AI.0 | E29: 0~0 | F29: 30840~100 | G29: TC41BC1A.Campo | H29: RETORNO DE CORRENTE DO MOTOR
C30: AI.1 | E30: 0~0 | F30: 30840~100 | G30: TC41BC1B.Campo | H30: RETORNO DE CORRENTE DO MOTOR
C31: AI.2 | E31: 0~0 | F31: 30840~100 | G31: TC41BC2A.Campo | H31: RETORNO DE CORRENTE DO MOTOR
C32: AI.3 | E32: 0~0 | F32: 30840~100 | G32: TC41BC2B.Campo | H32: RETORNO DE CORRENTE DO MOTOR
C33: AI.4 | E33: 0~0 | F33: 30840~100 | G33: TC41BC3A.Campo | H33: RETORNO DE CORRENTE DO MOTOR
C34: AI.5 | E34: 0~0 | F34: 30840~100 | G34: TC41BC3B.Campo | H34: RETORNO DE CORRENTE DO MOTOR
C35: AI.6 | E35: 0~0 | F35: 30840~100 | G35: TC41BC4A.Campo | H35: RETORNO DE CORRENTE DO MOTOR
C36: AI.7 | E36: 0~0 | F36: 30840~100 | G36: TC41BC4B.Campo | H36: RETORNO DE CORRENTE DO MOTOR
C37: SLOT 04 1734-IE8C/C : 08 AI
C38: IO | D38: Local | E38: Min | F38: Max | G38: TAG 's | H38: DESCRIÇÃO
C39: AI.0 | E39: 0~0 | F39: 30840~100 | G39: TC41BC5A.Campo | H39: RETORNO DE CORRENTE DO MOTOR
C40: AI.1 | E40: 0~0 | F40: 30840~100 | G40: TC41BC5B.Campo | H40: RETORNO DE CORRENTE DO MOTOR
C41: AI.2 | E41: 0~0 | F41: 30840~100 | G41: TC41BC6A.Campo | H41: RETORNO DE CORRENTE DO MOTOR
...

Sheet RemCCM2
C1: Milhão Ingredients Unidade - Rio Verde
C2: CPU CONTROLOGIX 1756-L73 192.100.3.1
C3: LISTA DE IO
G4: RESPONSAVEL TÉCNICO: Tallison Barros;
C6: 1734-AENTR/c RemCCM2 192.100.3.31
C7: SLOT 01 1734-IB8/C : 08 DI
C8: IO | D8: Local | E8: Min | F8: Max | G8: TAG 's | H8: DESCRIÇÃO
C9: DI.0 | E9: 0 | F9: 1 | G9: M47VR4.fb | H9: VÁLVULA ROTATIVA
C10: DI.1 | E10: 0 | F10: 1 | G10: M47VR5.fb | H10: VÁLVULA ROTATIVA
C11: DI.2 | E11: 0 | F11: 1 | G11: M47VR9.fb | H11: VÁLVULA ROTATIVA
C12: DI.3 | E12: 0 | F12: 1 | G12: M46VR10.fb | H12: VÁLVULA ROTATIVA
C13: DI.4 | E13: 0 | F13: 1 | G13: M47EX1.fb | H13: EXAUSTOR
C14: DI.5 | E14: 0 | F14: 1 | G14: M46GD1.fb | H14: DISTRIBUIDOR GIRATÓRIO - MOD. SDG/F - 5
C15: DI.6 | E15: 0 | F15: 1 | G15: M46GD2.fb | H15: DISTRIBUIDOR GIRATÓRIO - MOD. SDG/F - 5
C16: DI.7 | E16: 0 | F16: 1 | G16: M46GD3.fb | H16: DISTRIBUIDOR GIRATÓRIO - MOD. SDG/F - 5
C17: SLOT 02 1734-IB8/C : 08 DI
C18: IO | D18: Local | E18: Min | F18: Max | G18: TAG 's | H18: DESCRIÇÃO
C19: DI.0 | E19: 0 | F19: 1 | G19: M46GD4.fb | H19: DISTRIBUIDOR GIRATÓRIO - MOD. SDG/F - 5
C20: DI.1 | E20: 0 | F20: 1 | G20: M46VR6.fb | H20: VÁLVULA ROTATIVA
C21: DI.2 | E21: 0 | F21: 1 | G21: M46VR7.fb | H21: VÁLVULA ROTATIVA
C22: DI.3 | E22: 0 | F22: 1 | G22: M47EX2.fb | H22: EXTRATOR PLANO
C23: DI.4 | E23: 0 | F23: 1 | G23: M46GD5.fb | H23: DISTRIBUIDOR GIRATÓRIO - MOD. SDG/F - 6
C24: DI.5 | E24: 0 | F24: 1 | G24: M47VR11.fb | H24: VÁLVULA ROTATIVA
C25: DI.6 | E25: 0 | F25: 1 | G25: M47VR12.fb | H25: Sistema de tranportador Pneumático
C26: DI.7 | E26: 0 | F26: 1 | G26: M47VR15.fb | H26: VÁLVULA ROTATIVA
C27: SLOT 03 1734-IB8/C : 08 DI
C28: IO | D28: Local | E28: Min | F28: Max | G28: TAG 's | H28: DESCRIÇÃO
C29: DI.0 | E29: 0 | F29: 1 | G29: M46GD6.fb | H29: DISTRIBUIDOR GIRATÓRIO - MOD. SDG/F - 4
C30: DI.1 | E30: 0 | F30: 1 | G30: M46GD7.fb | H30: DISTRIBUIDOR GIRATÓRIO - MOD. SDG/F - 4
C31: DI.2 | E31: 0 | F31: 1 | G31: M45GD8.fb | H31: DISTRIBUIDOR GIRATÓRIO - MOD. SDG/F-4
C32: DI.3 | E32: 0 | F32: 1 | G32: M46EX3.fb | H32: EXAUSTOR
C33: DI.4 | E33: 0 | F33: 1 | G33: M47VR18.fb | H33: VÁLVULA ROTATIVA
C34: DI.5 | E34: 0 | F34: 1 | G34: M46VR20.fb | H34: VÁLVULA ROTATIVA
C35: DI.6 | E35: 0 | F35: 1 | G35: M45GD9.fb | H35: DISTRIBUIDOR GIRATÓRIO - MOD. SDG/F-4
C36: DI.7 | E36: 0 | F36: 1 | G36: M45GD10.fb | H36: DISTRIBUIDOR GIRATÓRIO - MOD. SDG/F-4
C37: SLOT 04 1734-IB8/C : 08 DI
C38: IO | D38: Local | E38: Min | F38: Max | G38: TAG 's | H38: DESCRIÇÃO
C39: DI.0 | E39: 0 | F39: 1 | G39: M44EX4.fb | H39: EXAUSTOR
C40: DI.1 | E40: 0 | F40: 1 | G40: M44VR45.fb | H40: VALVULA ROTATIVA
C41: DI.2 | E41: 0 | F41: 1 | G41: M47VR3.fb | H41: VÁLVULA ROTATIVA
...

Sheet RemCCM3
C1: Milhão Ingredients Unidade - Rio Verde
C2: CPU CONTROLOGIX 1756-L73 192.100.3.1
C3: LISTA DE IO
G4: RESPONSAVEL TÉCNICO: Tallison Barros;
C6: 1734-AENTR/c RemCCM3 192.100.3.50
C7: SLOT 01 1734-IB8/C : 08 DI
C8: IO | D8: Local | E8: Min | F8: Max | G8: TAG 's | H8: DESCRIÇÃO
C9: DI.0 | E9: 0 | F9: 1 | G9: M43AV3.fb | H9: SEPARADOR DE AR TARARA (MotorORIZAÇÃO NOVA)
C10: DI.1 | E10: 0 | F10: 1 | G10: M43AV4.fb | H10: SEPARADOR DE AR TARARA (MotorORIZAÇÃO NOVA)
C11: DI.2 | E11: 0 | F11: 1 | G11: M43AV5.fb | H11: SEPARADOR DE AR TARARA (MotorORIZAÇÃO NOVA)
C12: DI.3 | E12: 0 | F12: 1 | G12: M43AV6.fb | H12: SEPARADOR DE AR TARARA (MotorORIZAÇÃO NOVA)
C13: DI.4 | E13: 0 | F13: 1 | G13: M43RE8.fb | H13: ROSCA EXTRATORA
C14: DI.5 | E14: 0 | F14: 1 | G14: M42RE9.fb | H14: ROSCA EXTRATORA
C15: DI.6 | E15: 0 | F15: 1 | G15: M45VR42.fb | H15: VÁLVULA ROTATIVA
C16: DI.7 | E16: 0 | F16: 1 | G16: M42RE1.fb | H16: ROSCA TRANSPORTADORA
C17: SLOT 02 1734-IB8/C : 08 DI
C18: IO | D18: Local | E18: Min | F18: Max | G18: TAG 's | H18: DESCRIÇÃO
C19: DI.0 | E19: 0 | F19: 1 | G19: M42RE2.fb | H19: ROSCA TRANSPORTADORA
C20: DI.1 | E20: 0 | F20: 1 | G20: M42RE3.fb | H20: ROSCA TRANSPORTADORA
C21: DI.2 | E21: 0 | F21: 1 | G21: M42RE4.fb | H21: ROSCA TRANSPORTADORA
C22: DI.3 | E22: 0 | F22: 1 | G22: M42RE5.fb | H22: ROSCA TRANSPORTADORA
C23: DI.4 | E23: 0 | F23: 1 | G23: M43CD1A.fb | H23: CONDICIONADOR TÉRMICO - Motoror rosca 1
C24: DI.5 | E24: 0 | F24: 1 | G24: M43CD1B.fb | H24: CONDICIONADOR TÉRMICO - Motoror rosca 2
C25: DI.6 | E25: 0 | F25: 1 | G25: M43TV1.fb | H25: TURBOPENEIRA VERTICAL - MOD. STSF 40/80
C26: DI.7 | E26: 0 | F26: 1 | G26: M43TV2.fb | H26: TURBOPENEIRA VERTICAL - MOD. STSF 40/80
C27: SLOT 03 1734-IB8/C : 08 DI
C28: IO | D28: Local | E28: Min | F28: Max | G28: TAG 's | H28: DESCRIÇÃO
C29: DI.0 | E29: 0 | F29: 1 | G29: M43TV3.fb | H29: TURBOPENEIRA VERTICAL - MOD. STSF 40/80
C30: DI.1 | E30: 0 | F30: 1 | G30: M43TV4.fb | H30: TURBOPENEIRA VERTICAL - MOD. STSF 40/80
C31: DI.2 | E31: 0 | F31: 1 | G31: M43TV5.fb | H31: TURBOPENEIRA VERTICAL - MOD. STSF 40/80
C32: DI.3 | E32: 0 | F32: 1 | G32: M43TV6.fb | H32: TURBOPENEIRA VERTICAL - MOD. STSF 40/80
C33: DI.4 | E33: 0 | F33: 1 | G33: EMERGENCIA_CCM3.zsCampo | H33: EMERGENCIA_CCM3
C34: DI.5 | E34: 0 | F34: 1 | G34: M45VT26.fb | H34: VENTILADOR
C35: DI.6 | E35: 0 | F35: 1
C36: DI.7 | E36: 0 | F36: 1
C37: SLOT 04 1734-OB8/C : 08 DO
C38: IO | D38: Local | E38: Min | F38: Max | G38: TAG 's | H38: DESCRIÇÃO
C39: DO.0 | E39: 0 | F39: 1 | G39: M43AV3.saida | H39: SEPARADOR DE AR TARARA (MotorORIZAÇÃO NOVA)
C40: DO.1 | E40: 0 | F40: 1 | G40: M43AV4.saida | H40: SEPARADOR DE AR TARARA (MotorORIZAÇÃO NOVA)
C41: DO.2 | E41: 0 | F41: 1 | G41: M43AV5.saida | H41: SEPARADOR DE AR TARARA (MotorORIZAÇÃO NOVA)
...

Sheet RemCCM4
C1: Milhão Ingredients Unidade - Rio Verde
C2: CPU CONTROLOGIX 1756-L73 192.100.3.1
C3: LISTA DE IO
G4: RESPONSAVEL TÉCNICO: Tallison Barros;
C6: 1734-AENTR/c RemCCM4 192.100.3.86
C7: SLOT 01 1734-IB8/C : 08 DI
C8: IO | D8: Local | E8: Min | F8: Max | G8: TAG 's | H8: DESCRIÇÃO
C9: DI.0 | E9: 0 | F9: 1 | G9: M46BP3.fb | H9: TRANSP. PNEU. EM PRESSÃO (SOP.) - LINHA 01 - SUPER
C10: DI.1 | E10: 0 | F10: 1 | G10: M46BP10.fb | H10: TRANSP. PNEU. EM PRESSÃO (SOP.) - LINHA 07 - PEPSICO
C11: DI.2 | E11: 0 | F11: 1 | G11: M45BP12.fb | H11: TRANSP. PNEU. EM PRESSÃO (SOP.) - LINHA 09 - GRITS 170
C12: DI.3 | E12: 0 | F12: 1 | G12: M45BP13.fb | H12: TRANSP. PNEU. EM PRESSÃO (SOP.) - LINHA 10 - GRITS 1515
C13: DI.4 | E13: 0 | F13: 1 | G13: M46BP9.fb | H13: TRANSP. PNEU. EM PRESSÃO (SOP.) - LINHA 06 - DESMIL GROSSO
C14: DI.5 | E14: 0 | F14: 1 | G14: M47EL2.fb | H14: ELEVADOR DE CAÇAMBAS - MOD. EAP 50/50/17
C15: DI.6 | E15: 0 | F15: 1 | G15: M40RC4.fb | H15: ROSCA TRANSPORTADORA
C16: DI.7 | E16: 0 | F16: 1 | G16: M40RC5.fb | H16: ROSCA TRANSPORTADORA
C17: SLOT 02 1734-IB8/C : 08 DI
C18: IO | D18: Local | E18: Min | F18: Max | G18: TAG 's | H18: DESCRIÇÃO
C19: DI.0 | E19: 0 | F19: 1 | G19: M40RC6.fb | H19: ROSCA TRANSPORTADORA
C20: DI.1 | E20: 0 | F20: 1 | G20: M40RC1.fb | H20: ROSCA TRANSPORTADORA
C21: DI.2 | E21: 0 | F21: 1 | G21: M40RC2.fb | H21: ROSCA TRANSPORTADORA
C22: DI.3 | E22: 0 | F22: 1 | G22: M40RC7.fb | H22: ROSCA TRANSPORTADORA
C23: DI.4 | E23: 0 | F23: 1 | G23: M40VR35.fb | H23: VÁLVULA ROTATIVA
C24: DI.5 | E24: 0 | F24: 1 | G24: M40VR38.fb | H24: VÁLVULA ROTATIVA
C25: DI.6 | E25: 0 | F25: 1 | G25: M40VR39.fb | H25: VÁLVULA ROTATIVA
C26: DI.7 | E26: 0 | F26: 1 | G26: M40VR40.fb | H26: VÁLVULA ROTATIVA
C27: SLOT 03 1734-IB8/C : 08 DI
C28: IO | D28: Local | E28: Min | F28: Max | G28: TAG 's | H28: DESCRIÇÃO
C29: DI.0 | E29: 0 | F29: 1 | G29: M40VR28.fb | H29: VÁLVULA ROTATIVA
C30: DI.1 | E30: 0 | F30: 1 | G30: M40VR29.fb | H30: VÁLVULA ROTATIVA
C31: DI.2 | E31: 0 | F31: 1 | G31: M40VR30.fb | H31: VÁLVULA ROTATIVA
C32: DI.3 | E32: 0 | F32: 1 | G32: M40VR31.fb | H32: VÁLVULA ROTATIVA
C33: DI.4 | E33: 0 | F33: 1 | G33: M40VR32.fb | H33: VÁLVULA ROTATIVA
C34: DI.5 | E34: 0 | F34: 1 | G34: M40VR33.fb | H34: VÁLVULA ROTATIVA
C35: DI.6 | E35: 0 | F35: 1 | G35: M40VR34.fb | H35: VÁLVULA ROTATIVA
C36: DI.7 | E36: 0 | F36: 1 | G36: M40VR36.fb | H36: VÁLVULA ROTATIVA
C37: SLOT 04 1734-IB8/C : 08 DI
C38: IO | D38: Local | E38: Min | F38: Max | G38: TAG 's | H38: DESCRIÇÃO
C39: DI.0 | E39: 0 | F39: 1 | G39: M40VR37.fb | H39: VÁLVULA ROTATIVA
C40: DI.1 | E40: 0 | F40: 1 | G40: M24BH1.fb | H40: SISTEMA PARA BOMBEAMENTO DE ÁGUA
C41: DI.2 | E41: 0 | F41: 1 | G41: M23SU1.fb | H41: UNIDADES DE UMIDIFICAÇÃO PARA ROSCAS
...

Sheet RemCCM5
C1: Milhão Ingredients Unidade - Rio Verde
C2: CPU CONTROLOGIX 1756-L73 192.100.3.1
C3: LISTA DE IO
G4: RESPONSAVEL TÉCNICO: Tallison Barros;
C6: 1734-AENTR/c RemCCM5 192.100.3.200
C7: SLOT 01 1734-IB8/C : 08 DI
C8: IO | D8: Local | E8: Min | F8: Max | G8: TAG 's | H8: DESCRIÇÃO
C9: DI.0 | E9: 0 | F9: 1 | G9: M61PV1.fb | H9: PENEIRA DE SEGURANÇA - Motoror
C10: DI.1 | E10: 0 | F10: 1 | G10: M61PV2.fb | H10: PENEIRA DE SEGURANÇA - Motoror
C11: DI.2 | E11: 0 | F11: 1 | G11: M61PV3.fb | H11: PENEIRA DE SEGURANÇA - Motoror
C12: DI.3 | E12: 0 | F12: 1 | G12: M61PV4.fb | H12: PENEIRA DE SEGURANÇA - Motoror
C13: DI.4 | E13: 0 | F13: 1 | G13: M65PV5.fb | H13: PENEIRA DE SEGURANÇA - Motoror
C14: DI.5 | E14: 0 | F14: 1 | G14: M65PV6.fb | H14: PENEIRA DE SEGURANÇA - Motoror
C15: DI.6 | E15: 0 | F15: 1 | G15: M64PV7.fb | H15: PENEIRA DE SEGURANÇA - Motoror
C16: DI.7 | E16: 0 | F16: 1 | G16: M64PV8.fb | H16: PENEIRA DE SEGURANÇA - Motoror
C17: SLOT 02 1734-IB8/C : 08 DI
C18: IO | D18: Local | E18: Min | F18: Max | G18: TAG 's | H18: DESCRIÇÃO
C19: DI.0 | E19: 0 | F19: 1 | G19: M64PV9.fb | H19: PENEIRA DE SEGURANÇA - Motoror
C20: DI.1 | E20: 0 | F20: 1 | G20: M64PV10.fb | H20: PENEIRA DE SEGURANÇA - Motoror
C21: DI.2 | E21: 0 | F21: 1 | G21: M64PV11.fb | H21: PENEIRA DE SEGURANÇA - Motoror
C22: DI.3 | E22: 0 | F22: 1 | G22: M64PV12.fb | H22: PENEIRA DE SEGURANÇA - Motoror
C23: DI.4 | E23: 0 | F23: 1 | G23: M63TP1.fb | H23: TURBOPENEIRA - Motoror
C24: DI.5 | E24: 0 | F24: 1 | G24: M63TP2.fb | H24: TURBOPENEIRA - Motoror
C25: DI.6 | E25: 0 | F25: 1 | G25: M63PO1.fb | H25: POLIDORA - Motoror
C26: DI.7 | E26: 0 | F26: 1 | G26: M63PO2.fb | H26: POLIDORA - Motoror
C27: SLOT 03 1734-IB8/C : 08 DI
C28: IO | D28: Local | E28: Min | F28: Max | G28: TAG 's | H28: DESCRIÇÃO
C29: DI.0 | E29: 0 | F29: 1 | G29: M64BP1.fb | H29: SOPRADOR - Motoror
C30: DI.1 | E30: 0 | F30: 1 | G30: M66EL3.fb | H30: ELEVADOR DE CAÇAMBAS - MOD. 35/35/17 - EL19
C31: DI.2 | E31: 0 | F31: 1 | G31: M64RC2.fb | H31: ROSCA TRANSPORTADORA - Motoror
C32: DI.3 | E32: 0 | F32: 1 | G32: M60TR1.fb | H32: ESTEIRA DE ROLETES - Motoror
C33: DI.4 | E33: 0 | F33: 1 | G33: M60TR2.fb | H33: ESTEIRA DE ROLETES - Motoror
C34: DI.5 | E34: 0 | F34: 1 | G34: M60TR3.fb | H34: ESTEIRA DE ROLETES - Motoror
C35: DI.6 | E35: 0 | F35: 1 | G35: M60TR4.fb | H35: ESTEIRA DE ROLETES - Motoror
C36: DI.7 | E36: 0 | F36: 1 | G36: M63TC1.fb | H36: ESTEIRA TRANSPORTADORA - Motoror
C37: SLOT 04 1734-IB8/C : 08 DI
C38: IO | D38: Local | E38: Min | F38: Max | G38: TAG 's | H38: DESCRIÇÃO
C39: DI.0 | E39: 0 | F39: 1 | G39: M64RC1.fb | H39: ROSCA TRANSPORTADORA - Motoror
C40: DI.1 | E40: 0 | F40: 1 | G40: M65EV1.fb | H40: EXTRATOR - Motoror
C41: DI.2 | E41: 0 | F41: 1 | G41: M65EV2.fb | H41: EXTRATOR - Motoror
...

Sheet AENTR
C1: Milhão Ingredients Unidade - Rio Verde
C2: CPU CONTROLOGIX 1756-L73 192.100.3.1
C3: LISTA DE IO
G4: RESPONSAVEL TÉCNICO: Tallison Barros;
C6: 1747-AENTR AENTR 192.100.3.119
C7: SLOT 01 1746-IB32 : 32 DI
C8: IO | D8: Local | E8: Min | F8: Max | G8: TAG 's | H8: DESCRIÇÃO
C9: DI.0 | E9: 0 | F9: 1
C10: DI.1 | E10: 0 | F10: 1
C11: DI.2 | E11: 0 | F11: 1
C12: DI.3 | E12: 0 | F12: 1
C13: DI.4 | E13: 0 | F13: 1
C14: DI.5 | E14: 0 | F14: 1
C15: DI.6 | E15: 0 | F15: 1
C16: DI.7 | E16: 0 | F16: 1
C17: DI.8 | E17: 0 | F17: 1
C18: DI.9 | E18: 0 | F18: 1 | G18: M27EL2.fb | H18: ELEVADOR DE CAÇAMBAS - ECAN0025
C19: DI.10 | E19: 0 | F19: 1
C20: DI.11 | E20: 0 | F20: 1
C21: DI.12 | E21: 0 | F21: 1 | G21: M23RN13.fb | H21: Rosca Molhadora da Degerminadora (Antiga RMMD7)
C22: DI.13 | E22: 0 | F22: 1 | G22: M23RN14.fb | H22: Rosca Molhadora da Degerminadora (Antiga RMMD8)
C23: DI.14 | E23: 0 | F23: 1 | G23: M23RN15.fb | H23: Rosca Molhadora da Degerminadora (Antiga RMMD9)
C24: DI.15 | E24: 0 | F24: 1 | G24: M23RN16.fb | H24: Rosca Molhadora da Degerminadora (Antiga RMMD10)
C25: DI.16 | E25: 0 | F25: 1 | G25: M23RN17.fb | H25: Rosca Molhadora da Degerminadora (Antiga RMMD11)
C26: DI.17 | E26: 0 | F26: 1 | G26: M23RN18.fb | H26: Rosca Molhadora da Degerminadora (Antiga RMMD12)
C27: DI.18 | E27: 0 | F27: 1 | G27: M21VT7.fb | H27: Ventilador da Degerminadora (Antiga VTD7)
C28: DI.19 | E28: 0 | F28: 1 | G28: M21VT8.fb | H28: Ventilador da Degerminadora (Antiga VTD8)
C29: DI.20 | E29: 0 | F29: 1 | G29: M21VT9.fb | H29: Ventilador da Degerminadora (Antiga VTD9)
C30: DI.21 | E30: 0 | F30: 1 | G30: M21VT10.fb | H30: Ventilador da Degerminadora (Antiga VTD10)
C31: DI.22 | E31: 0 | F31: 1 | G31: M21VT11.fb | H31: Ventilador da Degerminadora (Antiga VTD11)
C32: DI.23 | E32: 0 | F32: 1 | G32: M21VT12.fb | H32: Ventilador da Degerminadora (Antiga VTD12)
C33: DI.24 | E33: 0 | F33: 1
C34: DI.25 | E34: 0 | F34: 1 | G34: M21RE7.fb | H34: Rosca Alimentadora da Degerminadora (Antiga RAD7)
C35: DI.26 | E35: 0 | F35: 1 | G35: M21RE8.fb | H35: Rosca Alimentadora da Degerminadora (Antiga RAD8)
C36: DI.27 | E36: 0 | F36: 1 | G36: M21RE9.fb | H36: Rosca Alimentadora da Degerminadora (Antiga RAD9)
C37: DI.28 | E37: 0 | F37: 1 | G37: M21RE10.fb | H37: Rosca Alimentadora da Degerminadora (Antiga RAD10)
C38: DI.29 | E38: 0 | F38: 1 | G38: M21RE11.fb | H38: Rosca Alimentadora da Degerminadora (Antiga RAD11)
C39: DI.30 | E39: 0 | F39: 1 | G39: M21RE12.fb | H39: Rosca Alimentadora da Degerminadora (Antiga RAD12)
C40: DI.31 | E40: 0 | F40: 1 | G40: M21VR48.fb | H40: VÁLVULA ROTATIVA DO EXAUSTOR TERMOPNEUMÁTICO
C41: SLOT 02 1746-IB32 : 32 DI
...

Sheet AENT1
C1: Milhão Ingredients Unidade - Rio Verde
C2: CPU CONTROLOGIX 1756-L73 192.100.3.1
C3: LISTA DE IO
G4: RESPONSAVEL TÉCNICO: Tallison Barros;
C6: 1794-AENT AENT1 192.100.3.120
C7: SLOT 00 1794-IE8/B : 08 AI
C8: IO | D8: Local | E8: Min | F8: Max | G8: TAG 's | H8: DESCRIÇÃO
C9: AI.0 | E9: 0~0 | F9: 30840~100 | G9: S21RP1.NIVEL.PVRAW
C10: AI.1 | E10: 0~0 | F10: 30840~100 | G10: S21RP2.NIVEL.PVRAW
C11: AI.2 | E11: 0~0 | F11: 30840~100 | G11: S21RP3.NIVEL.PVRAW
C12: AI.3 | E12: 0~0 | F12: 30840~100 | G12: S21RP4.NIVEL.PVRAW
C13: AI.4 | E13: 0~0 | F13: 30840~100 | G13: S21RP5.NIVEL.PVRAW
C14: AI.5 | E14: 0~0 | F14: 30840~100 | G14: S21RP6.NIVEL.PVRAW
C15: AI.6 | E15: 0~0 | F15: 30840~100
C16: AI.7 | E16: 0~0 | F16: 30840~100
C17: SLOT 01 1794-IE8/B : 08 AI
C18: IO | D18: Local | E18: Min | F18: Max | G18: TAG 's | H18: DESCRIÇÃO
C19: AI.0 | E19: 0~0 | F19: 30840~100
C20: AI.1 | E20: 0~0 | F20: 30840~100
C21: AI.2 | E21: 0~0 | F21: 30840~100 | G21: S32RP6.Nivel.PVRaw
C22: AI.3 | E22: 0~0 | F22: 30840~100 | G22: S32RP5.Nivel.PVRaw
C23: AI.4 | E23: 0~0 | F23: 30840~100 | G23: S21RP19.Nivel.PVRaw
C24: AI.5 | E24: 0~0 | F24: 30840~100 | G24: S21RP20.Nivel.PVRaw
C25: AI.6 | E25: 0~0 | F25: 30840~100 | G25: S21RP21.Nivel.PVRaw
C26: AI.7 | E26: 0~0 | F26: 30840~100 | G26: S32RP4.Nivel.PVRaw
C27: SLOT 02 1794-OE8/A : 12 AO
C28: IO | D28: Local | E28: Min | F28: Max | G28: TAG 's | H28: DESCRIÇÃO
C29: AO.0
C30: AO.1
C31: AO.2
C32: AO.3
C33: AO.4
C34: AO.5
C35: AO.6
C36: AO.7
C37: SLOT 03 1794-IB32/A : 32 DI
C38: IO | D38: Local | E38: Min | F38: Max | G38: TAG 's | H38: DESCRIÇÃO
C39: DI.0 | E39: 0 | F39: 1
C40: DI.1 | E40: 0 | F40: 1
C41: DI.2 | E41: 0 | F41: 1
...

Sheet AENT2
C1: Milhão Ingredients Unidade - Rio Verde
C2: CPU CONTROLOGIX 1756-L73 192.100.3.1
C3: LISTA DE IO
G4: RESPONSAVEL TÉCNICO: Tallison Barros;
C6: 1794-AENT AENT2 192.100.3.121
C7: SLOT 00 1794-IB32/A : 32 DI
C8: IO | D8: Local | E8: Min | F8: Max | G8: TAG 's | H8: DESCRIÇÃO
C9: DI.0 | E9: 0 | F9: 1 | G9: M21DG1.GiroTimeOut
C10: DI.1 | E10: 0 | F10: 1 | G10: M21DG2.GiroTimeOut
C11: DI.2 | E11: 0 | F11: 1 | G11: M21DG3.GiroTimeOut
C12: DI.3 | E12: 0 | F12: 1 | G12: M21DG4.GiroTimeOut
C13: DI.4 | E13: 0 | F13: 1 | G13: M21DG5.GiroTimeOut
C14: DI.5 | E14: 0 | F14: 1 | G14: M21DG6.GiroTimeOut
C15: DI.6 | E15: 0 | F15: 1 | G15: M21DG7.GiroTimeOut
C16: DI.7 | E16: 0 | F16: 1 | G16: M21DG8.GiroTimeOut
C17: DI.8 | E17: 0 | F17: 1 | G17: M21DG9.GiroTimeOut
C18: DI.9 | E18: 0 | F18: 1 | G18: M21DG10.GiroTimeOut
C19: DI.10 | E19: 0 | F19: 1 | G19: M21DG11.GiroTimeOut
C20: DI.11 | E20: 0 | F20: 1 | G20: M21DG12.GiroTimeOut
... C26: DI.17 | E26: 0 | F26: 1 | G26: M21DG18.GiroTimeOut
C27: DI.18 | E27: 0 | F27: 1
C28: DI.19 | E28: 0 | F28: 1
C29: DI.20 | E29: 0 | F29: 1
C30: DI.21 | E30: 0 | F30: 1
C31: DI.22 | E31: 0 | F31: 1 | G31: M21VT34.fb
C32: DI.23 | E32: 0 | F32: 1 | G32: M23VT44.fb
C33: DI.24 | E33: 0 | F33: 1 | G33: M23VT49.fb
C34: DI.25 | E34: 0 | F34: 1 | G34: M22VT29.fb
C35: DI.26 | E35: 0 | F35: 1 | G35: M22VT39.fb
C36: DI.27 | E36: 0 | F36: 1 | G36: M21VR34.fb
C37: DI.28 | E37: 0 | F37: 1 | G37: M23VR44.fb
C38: DI.29 | E38: 0 | F38: 1 | G38: M23VR49.fb
C39: DI.30 | E39: 0 | F39: 1 | G39: M22VR29.fb
C40: DI.31 | E40: 0 | F40: 1 | G40: M22VR39.fb
C41: SLOT 01 1794-IB32/A : 32 DI
C42: IO | D42: Local | E42: Min | F42: Max | G42: TAG 's | H42: DESCRIÇÃO
C43: DI.0 | E43: 0 | F43: 1 | G43: M21EX4.fb
C44: DI.1 | E44: 0 | F44: 1 | G44: M23EX6.fb
C45: DI.2 | E45: 0 | F45: 1 | G45: M23EX7.fb
C46: DI.3 | E46: 0 | F46: 1 | G46: M22EX3.fb
...

Sheet Remota1_CCM
C1: Milhão Ingredients Unidade - Rio Verde
C2: CPU CONTROLOGIX 1756-L73 192.100.3.1
C3: LISTA DE IO
G4: RESPONSAVEL TÉCNICO: Tallison Barros;
C6: 1794-AENT Remota1_CCM 192.100.3.122
C7: SLOT 00 1794-IB32/A : 32 DI
C8: IO | D8: Local | E8: Min | F8: Max | G8: TAG 's | H8: DESCRIÇÃO
C9: DI.0 | E9: 0 | F9: 1
C10: DI.1 | E10: 0 | F10: 1
C11: DI.2 | E11: 0 | F11: 1
C12: DI.3 | E12: 0 | F12: 1 | G12: M36EL3.fb
C13: DI.4 | E13: 0 | F13: 1 | G13: M44PL3.fb
C14: DI.5 | E14: 0 | F14: 1
C15: DI.6 | E15: 0 | F15: 1
C16: DI.7 | E16: 0 | F16: 1
C17: DI.8 | E17: 0 | F17: 1
C18: DI.9 | E18: 0 | F18: 1
C19: DI.10 | E19: 0 | F19: 1
C20: DI.11 | E20: 0 | F20: 1
C21: DI.12 | E21: 0 | F21: 1 | G21: M44PL7.fb
C22: DI.13 | E22: 0 | F22: 1
C23: DI.14 | E23: 0 | F23: 1
C24: DI.15 | E24: 0 | F24: 1 | G24: M44PL1.fb
C25: DI.16 | E25: 0 | F25: 1 | G25: M36EL6.fb
C26: DI.17 | E26: 0 | F26: 1
C27: DI.18 | E27: 0 | F27: 1
C28: DI.19 | E28: 0 | F28: 1
C29: DI.20 | E29: 0 | F29: 1
C30: DI.21 | E30: 0 | F30: 1
C31: DI.22 | E31: 0 | F31: 1
C32: DI.23 | E32: 0 | F32: 1
C33: DI.24 | E33: 0 | F33: 1
C34: DI.25 | E34: 0 | F34: 1
C35: DI.26 | E35: 0 | F35: 1
C36: DI.27 | E36: 0 | F36: 1 | G36: M46VT26.fb
C37: DI.28 | E37: 0 | F37: 1 | G37: RFF_MOA
C38: DI.29 | E38: 0 | F38: 1
C39: DI.30 | E39: 0 | F39: 1
C40: DI.31 | E40: 0 | F40: 1
C41: SLOT 01 1794-IB32/A : 32 DI
...

Sheet Remota2_CCM
C1: Milhão Ingredients Unidade - Rio Verde
C2: CPU CONTROLOGIX 1756-L73 192.100.3.1
C3: LISTA DE IO
G4: RESPONSAVEL TÉCNICO: Tallison Barros;
C6: 1794-AENT Remota2_CCM 192.100.3.123
C7: SLOT 00 1794-IB32/A : 32 DI
C8: IO | D8: Local | E8: Min | F8: Max | G8: TAG 's | H8: DESCRIÇÃO
C9: DI.0 | E9: 0 | F9: 1
C10: DI.1 | E10: 0 | F10: 1
C11: DI.2 | E11: 0 | F11: 1
C12: DI.3 | E12: 0 | F12: 1
C13: DI.4 | E13: 0 | F13: 1 | G13: M67EL4.fb
C14: DI.5 | E14: 0 | F14: 1
C15: DI.6 | E15: 0 | F15: 1
C16: DI.7 | E16: 0 | F16: 1
C17: DI.8 | E17: 0 | F17: 1
C18: DI.9 | E18: 0 | F18: 1
C19: DI.10 | E19: 0 | F19: 1
C20: DI.11 | E20: 0 | F20: 1
C21: DI.12 | E21: 0 | F21: 1
C22: DI.13 | E22: 0 | F22: 1 | G22: M37EL7.fb
C23: DI.14 | E23: 0 | F23: 1
C24: DI.15 | E24: 0 | F24: 1
C25: DI.16 | E25: 0 | F25: 1 | G25: M26EL1.fb
C26: DI.17 | E26: 0 | F26: 1
C27: DI.18 | E27: 0 | F27: 1
C28: DI.19 | E28: 0 | F28: 1
C29: DI.20 | E29: 0 | F29: 1
C30: DI.21 | E30: 0 | F30: 1
C31: DI.22 | E31: 0 | F31: 1
C32: DI.23 | E32: 0 | F32: 1
C33: DI.24 | E33: 0 | F33: 1
C34: DI.25 | E34: 0 | F34: 1
C35: DI.26 | E35: 0 | F35: 1
C36: DI.27 | E36: 0 | F36: 1
C37: DI.28 | E37: 0 | F37: 1
... C40: DI.31 | E40: 0 | F40: 1
C41: SLOT 01 1794-IB32/A : 32 DI
C42: IO | D42: Local | E42: Min | F42: Max | G42: TAG 's | H42: DESCRIÇÃO
C43: DI.0 | E43: 0 | F43: 1
...

Sheet Remota3_CCM
C1: Milhão Ingredients Unidade - Rio Verde
C2: CPU CONTROLOGIX 1756-L73 192.100.3.1
C3: LISTA DE IO
G4: RESPONSAVEL TÉCNICO: Tallison Barros;
C6: 1794-AENT Remota3_CCM 192.100.3.124
C7: SLOT 00 1794-OB32P/A : 32 DO
C8: IO | D8: Local | E8: Min | F8: Max | G8: TAG 's | H8: DESCRIÇÃO
C9: DO.0 | E9: 0 | F9: 1
C10: DO.1 | E10: 0 | F10: 1
C11: DO.2 | E11: 0 | F11: 1 | G11: ACIONA_SIRENA | H11: Sirenes.Audio_out.0
C12: DO.3 | E12: 0 | F12: 1 | G12: M24VR54.saida
C13: DO.4 | E13: 0 | F13: 1
C14: DO.5 | E14: 0 | F14: 1
C15: DO.6 | E15: 0 | F15: 1
C16: DO.7 | E16: 0 | F16: 1 | G16: M36RC4.saida
C17: DO.8 | E17: 0 | F17: 1 | J17: SLOT 04+G111:G1421794-OB32P/A : 32 DO
C18: DO.9 | E18: 0 | F18: 1 | G18: M35VR2.saida | H18: DUPLICADA SAIDA
C19: DO.10 | E19: 0 | F19: 1 | G19: M35VR2.saida | H19: DUPLICADA SAIDA
C20: DO.11 | E20: 0 | F20: 1
C21: DO.12 | E21: 0 | F21: 1
C22: DO.13 | E22: 0 | F22: 1
C23: DO.14 | E23: 0 | F23: 1
C24: DO.15 | E24: 0 | F24: 1
C25: DO.16 | E25: 0 | F25: 1
C26: DO.17 | E26: 0 | F26: 1
C27: DO.18 | E27: 0 | F27: 1
C28: DO.19 | E28: 0 | F28: 1
C29: DO.20 | E29: 0 | F29: 1
C30: DO.21 | E30: 0 | F30: 1
C31: DO.22 | E31: 0 | F31: 1
... C36: DO.27 | E36: 0 | F36: 1
C37: DO.28 | E37: 0 | F37: 1 | G37: M10vt1.saida
C38: DO.29 | E38: 0 | F38: 1
C39: DO.30 | E39: 0 | F39: 1 | G39: M27VR29.saida
C40: DO.31 | E40: 0 | F40: 1 | G40: M36AV3.saida
C41: SLOT 01 1794-OB32P/A : 32 DO
C42: IO | D42: Local | E42: Min | F42: Max | G42: TAG 's | H42: DESCRIÇÃO
C43: DO.0 | E43: 0 | F43: 1
C44: DO.1 | E44: 0 | F44: 1
C45: DO.2 | E45: 0 | F45: 1 | G45: M36AV9.saida
...

Sheet Rem1
C1: Milhão Ingredients Unidade - Rio Verde
C2: CPU CONTROLOGIX 1756-L73 192.100.3.1
C3: LISTA DE IO
G4: RESPONSAVEL TÉCNICO: Tallison Barros;
C6: 1734-AENTR/c Rem1 192.100.3.160
C7: SLOT 01 1734-IB8/C : 08 DI
C8: IO | D8: Local | E8: Min | F8: Max | G8: TAG 's | H8: DESCRIÇÃO
C9: DI.0 | E9: 0 | F9: 1
C10: DI.1 | E10: 0 | F10: 1
C11: DI.2 | E11: 0 | F11: 1
C12: DI.3 | E12: 0 | F12: 1
C13: DI.4 | E13: 0 | F13: 1 | G13: MX40VR40.ZsCampo
C14: DI.5 | E14: 0 | F14: 1 | G14: MX40VR39.ZsCampo
C15: DI.6 | E15: 0 | F15: 1 | G15: MX40VR38.ZsCampo
C16: DI.7 | E16: 0 | F16: 1 | G16: MX40VR37.ZsCampo
C17: SLOT 02 1734-IB8/C : 08 DI
C18: IO | D18: Local | E18: Min | F18: Max | G18: TAG 's | H18: DESCRIÇÃO
C19: DI.0 | E19: 0 | F19: 1 | G19: MX40VR36.ZsCampo
C20: DI.1 | E20: 0 | F20: 1 | G20: MX40VR35.ZsCampo
C21: DI.2 | E21: 0 | F21: 1 | G21: MX40VR34.ZsCampo
C22: DI.3 | E22: 0 | F22: 1 | G22: MX40VR33.ZsCampo
C23: DI.4 | E23: 0 | F23: 1 | G23: MX40VR32.ZsCampo
C24: DI.5 | E24: 0 | F24: 1 | G24: MX40VR31.ZsCampo
C25: DI.6 | E25: 0 | F25: 1 | G25: MX40VR30.ZsCampo
C26: DI.7 | E26: 0 | F26: 1 | G26: MX40VR29.ZsCampo
C27: SLOT 03 1734-IB8/C : 08 DI
C28: IO | D28: Local | E28: Min | F28: Max | G28: TAG 's | H28: DESCRIÇÃO
C29: DI.0 | E29: 0 | F29: 1 | G29: MX40VR28.ZsCampo
C30: DI.1 | E30: 0 | F30: 1 | G30: MX40VR27.ZsCampo
C31: DI.2 | E31: 0 | F31: 1 | G31: MX40VR26.ZsCampo
C32: DI.3 | E32: 0 | F32: 1 | G32: MX40VR25.ZsCampo
C33: DI.4 | E33: 0 | F33: 1 | G33: MX40VR24.ZsCampo
C34: DI.5 | E34: 0 | F34: 1 | G34: V40GP6.fb_direita
C35: DI.6 | E35: 0 | F35: 1 | G35: V40GP6.fb_esquerda
C36: DI.7 | E36: 0 | F36: 1 | G36: V40GP5.fb_direita
C37: SLOT 04 1734-IB8/C : 08 DI
C38: IO | D38: Local | E38: Min | F38: Max | G38: TAG 's | H38: DESCRIÇÃO
C39: DI.0 | E39: 0 | F39: 1 | G39: V40GP5.fb_esquerda
C40: DI.1 | E40: 0 | F40: 1 | G40: V40GP4.fb_direita
C41: DI.2 | E41: 0 | F41: 1 | G41: V40GP4.fb_esquerda
...

Sheet Rem2
C1: Milhão Ingredients Unidade - Rio Verde
C2: CPU CONTROLOGIX 1756-L73 192.100.3.1
C3: LISTA DE IO
G4: RESPONSAVEL TÉCNICO: Tallison Barros;
C6: 1734-AENTR/c Rem2 192.100.3.161
C7: SLOT 01 1734-IB8/C : 08 DI
C8: IO | D8: Local | E8: Min | F8: Max | G8: TAG 's | H8: DESCRIÇÃO
C9: DI.0 | E9: 0 | F9: 1 | G9: FE42RE1
C10: DI.1 | E10: 0 | F10: 1 | G10: MX24VR54.ZsCampo
C11: DI.2 | E11: 0 | F11: 1 | G11: FE42RE3
C12: DI.3 | E12: 0 | F12: 1 | G12: FE42RE4
C13: DI.4 | E13: 0 | F13: 1 | G13: MX24VR55.ZsCampo
C14: DI.5 | E14: 0 | F14: 1 | G14: FE42RE9
C15: DI.6 | E15: 0 | F15: 1 | G15: FE43RC1
C16: DI.7 | E16: 0 | F16: 1 | G16: FE43RC2
C17: SLOT 02 1734-IB8/C : 08 DI
C18: IO | D18: Local | E18: Min | F18: Max | G18: TAG 's | H18: DESCRIÇÃO
C19: DI.0 | E19: 0 | F19: 1 | G19: FE43RE8
C20: DI.1 | E20: 0 | F20: 1 | G20: FE63RC4
C21: DI.2 | E21: 0 | F21: 1 | G21: MX401I.ZsCampo
C22: DI.3 | E22: 0 | F22: 1 | G22: MX402I.ZsCampo
C23: DI.4 | E23: 0 | F23: 1 | G23: MX403I.ZsCampo
C24: DI.5 | E24: 0 | F24: 1 | G24: MX404I.ZsCampo
C25: DI.6 | E25: 0 | F25: 1 | G25: MX405I.ZsCampo
C26: DI.7 | E26: 0 | F26: 1 | G26: MX406I.ZsCampo
C27: SLOT 03 1734-IB8/C : 08 DI
C28: IO | D28: Local | E28: Min | F28: Max | G28: TAG 's | H28: DESCRIÇÃO
C29: DI.0 | E29: 0 | F29: 1 | G29: MX407I.ZsCampo
C30: DI.1 | E30: 0 | F30: 1 | G30: MX408I.ZsCampo
C31: DI.2 | E31: 0 | F31: 1 | G31: MX409I.ZsCampo
C32: DI.3 | E32: 0 | F32: 1 | G32: MX410I.ZsCampo
C33: DI.4 | E33: 0 | F33: 1 | G33: MX411I.ZsCampo
C34: DI.5 | E34: 0 | F34: 1 | G34: MX412I.ZsCampo
C35: DI.6 | E35: 0 | F35: 1 | G35: MN42MG1.ZsCampo
C36: DI.7 | E36: 0 | F36: 1 | G36: MN42MG2.ZsCampo
C37: SLOT 04 1734-IB8/C : 08 DI
C38: IO | D38: Local | E38: Min | F38: Max | G38: TAG 's | H38: DESCRIÇÃO
C39: DI.0 | E39: 0 | F39: 1
C40: DI.1 | E40: 0 | F40: 1 | G40: MN42MD2.ZsCampo
C41: DI.2 | E41: 0 | F41: 1 | G41: MX42MD3.ZsCampo
...

Sheet Rem3
C1: Milhão Ingredients Unidade - Rio Verde
C2: CPU CONTROLOGIX 1756-L73 192.100.3.1
C3: LISTA DE IO
G4: RESPONSAVEL TÉCNICO: Tallison Barros;
C6: 1734-AENTR/c Rem3 192.100.3.162
C7: SLOT 01 1734-IB8/C : 08 DI
C8: IO | D8: Local | E8: Min | F8: Max | G8: TAG 's | H8: DESCRIÇÃO
C9: DI.0 | E9: 0 | F9: 1 | G9: MX44VR21.ZsCampo
C10: DI.1 | E10: 0 | F10: 1 | G10: V34VP9.fb_direita
C11: DI.2 | E11: 0 | F11: 1 | G11: V34VP9.fb_esquerda
C12: DI.3 | E12: 0 | F12: 1 | G12: V34VP8.fb_direita
C13: DI.4 | E13: 0 | F13: 1 | G13: V34VP8.fb_esquerda
C14: DI.5 | E14: 0 | F14: 1 | G14: V34VP70.fb_direita
C15: DI.6 | E15: 0 | F15: 1 | G15: V34VP70.fb_esquerda
C16: DI.7 | E16: 0 | F16: 1 | G16: V34VP7.fb_direita
C17: SLOT 02 1734-IB8/C : 08 DI
C18: IO | D18: Local | E18: Min | F18: Max | G18: TAG 's | H18: DESCRIÇÃO
C19: DI.0 | E19: 0 | F19: 1 | G19: V34VP7.fb_esquerda
C20: DI.1 | E20: 0 | F20: 1 | G20: V34VP69.fb_direita
C21: DI.2 | E21: 0 | F21: 1 | G21: V34VP69.fb_esquerda
C22: DI.3 | E22: 0 | F22: 1 | G22: V34VP68.fb_direita
C23: DI.4 | E23: 0 | F23: 1 | G23: V34VP68.fb_esquerda
C24: DI.5 | E24: 0 | F24: 1 | G24: V34VP67.fb_direita
C25: DI.6 | E25: 0 | F25: 1 | G25: V34VP67.fb_esquerda
C26: DI.7 | E26: 0 | F26: 1 | G26: V34VP66.fb_direita
C27: SLOT 03 1734-IB8/C : 08 DI
C28: IO | D28: Local | E28: Min | F28: Max | G28: TAG 's | H28: DESCRIÇÃO
C29: DI.0 | E29: 0 | F29: 1 | G29: V34VP66.fb_esquerda
C30: DI.1 | E30: 0 | F30: 1 | G30: V34VP65.fb_direita
C31: DI.2 | E31: 0 | F31: 1 | G31: V34VP65.fb_esquerda
C32: DI.3 | E32: 0 | F32: 1 | G32: V34VP64.fb_direita
C33: DI.4 | E33: 0 | F33: 1 | G33: V34VP64.fb_esquerda
C34: DI.5 | E34: 0 | F34: 1 | G34: V34VP63.fb_direita
C35: DI.6 | E35: 0 | F35: 1 | G35: V34VP63.fb_esquerda
C36: DI.7 | E36: 0 | F36: 1 | G36: V34VP62.fb_direita
C37: SLOT 04 1734-IB8/C : 08 DI
C38: IO | D38: Local | E38: Min | F38: Max | G38: TAG 's | H38: DESCRIÇÃO
C39: DI.0 | E39: 0 | F39: 1 | G39: V34VP62.fb_esquerda
C40: DI.1 | E40: 0 | F40: 1 | G40: V34VP61.fb_direita
C41: DI.2 | E41: 0 | F41: 1 | G41: V34VP61.fb_esquerda
...

Sheet Rem4
C1: Milhão Ingredients Unidade - Rio Verde
C2: CPU CONTROLOGIX 1756-L73 192.100.3.1
C3: LISTA DE IO
G4: RESPONSAVEL TÉCNICO: Tallison Barros;
C6: 1734-AENTR/c Rem4 192.100.3.163
C7: SLOT 01 1734-IB8/C : 08 DI
C8: IO | D8: Local | E8: Min | F8: Max | G8: TAG 's | H8: DESCRIÇÃO
C9: DI.0 | E9: 0 | F9: 1 | G9: MX45VR42.ZsCampo
C10: DI.1 | E10: 0 | F10: 1 | G10: V45VP9.fb_direita
C11: DI.2 | E11: 0 | F11: 1 | G11: V45VP9.fb_esquerda
C12: DI.3 | E12: 0 | F12: 1 | G12: V45VP8.fb_direita
C13: DI.4 | E13: 0 | F13: 1 | G13: V45VP8.fb_esquerda
C14: DI.5 | E14: 0 | F14: 1 | G14: V45VP7.fb_direita
C15: DI.6 | E15: 0 | F15: 1 | G15: V45VP7.fb_esquerda
C16: DI.7 | E16: 0 | F16: 1 | G16: V45VP6.fb_direita
C17: SLOT 02 1734-IB8/C : 08 DI
C18: IO | D18: Local | E18: Min | F18: Max | G18: TAG 's | H18: DESCRIÇÃO
C19: DI.0 | E19: 0 | F19: 1 | G19: V45VP6.fb_esquerda
C20: DI.1 | E20: 0 | F20: 1 | G20: V45VP5.fb_direita
C21: DI.2 | E21: 0 | F21: 1 | G21: V45VP5.fb_esquerda
C22: DI.3 | E22: 0 | F22: 1 | G22: V45VP4.fb_direita
C23: DI.4 | E23: 0 | F23: 1 | G23: V45VP4.fb_esquerda
C24: DI.5 | E24: 0 | F24: 1 | G24: V45VP3.fb_direita
C25: DI.6 | E25: 0 | F25: 1 | G25: V45VP3.fb_esquerda
C26: DI.7 | E26: 0 | F26: 1 | G26: V45VP2.fb_direita
C27: SLOT 03 1734-IB8/C : 08 DI
C28: IO | D28: Local | E28: Min | F28: Max | G28: TAG 's | H28: DESCRIÇÃO
C29: DI.0 | E29: 0 | F29: 1 | G29: V45VP2.fb_esquerda
C30: DI.1 | E30: 0 | F30: 1 | G30: V45VP1.fb_direita
C31: DI.2 | E31: 0 | F31: 1 | G31: V45VP1.fb_esquerda
C32: DI.3 | E32: 0 | F32: 1 | G32: V45VP16.fb_direita
C33: DI.4 | E33: 0 | F33: 1 | G33: V45VP16.fb_esquerda
C34: DI.5 | E34: 0 | F34: 1 | G34: V45VP15.fb_direita
C35: DI.6 | E35: 0 | F35: 1 | G35: V45VP15.fb_esquerda
C36: DI.7 | E36: 0 | F36: 1 | G36: V45VP14.fb_direita
C37: SLOT 04 1734-IB8/C : 08 DI
C38: IO | D38: Local | E38: Min | F38: Max | G38: TAG 's | H38: DESCRIÇÃO
C39: DI.0 | E39: 0 | F39: 1 | G39: V45VP14.fb_esquerda
C40: DI.1 | E40: 0 | F40: 1 | G40: V45VP13.fb_direita
C41: DI.2 | E41: 0 | F41: 1 | G41: V45VP13.fb_esquerda
...

Sheet Rem5
C1: Milhão Ingredients Unidade - Rio Verde
C2: CPU CONTROLOGIX 1756-L73 192.100.3.1
C3: LISTA DE IO
G4: RESPONSAVEL TÉCNICO: Tallison Barros;
C6: 1734-AENTR/c Rem5 192.100.3.164
C7: SLOT 01 1734-IB8/C : 08 DI
C8: IO | D8: Local | E8: Min | F8: Max | G8: TAG 's | H8: DESCRIÇÃO
C9: DI.0 | E9: 0 | F9: 1 | G9: V62VP9.fb_direita
C10: DI.1 | E10: 0 | F10: 1 | G10: V62VP9.fb_esquerda
C11: DI.2 | E11: 0 | F11: 1 | G11: RUN62FT21.ZsCampo
C12: DI.3 | E12: 0 | F12: 1 | G12: ALA62FT21.ZsCampo
C13: DI.4 | E13: 0 | F13: 1 | G13: SK60TR1
C14: DI.5 | E14: 0 | F14: 1 | G14: SK60TR2
C15: DI.6 | E15: 0 | F15: 1 | G15: SK60TR3
C16: DI.7 | E16: 0 | F16: 1 | G16: SK60TR4
C17: SLOT 02 1734-IB8/C : 08 DI
C18: IO | D18: Local | E18: Min | F18: Max | G18: TAG 's | H18: DESCRIÇÃO
C19: DI.0 | E19: 0 | F19: 1 | G19: M66EL3_HZ
C20: DI.1 | E20: 0 | F20: 1 | G20: FE62RE13
C21: DI.2 | E21: 0 | F21: 1 | G21: FE62RE14
C22: DI.3 | E22: 0 | F22: 1 | G22: MX62RP7.ZsCampo
C23: DI.4 | E23: 0 | F23: 1 | G23: MX62RP8.ZsCampo
C24: DI.5 | E24: 0 | F24: 1 | G24: MX62VR14.ZsCampo
C25: DI.6 | E25: 0 | F25: 1 | G25: MX61VR15.ZsCampo
C26: DI.7 | E26: 0 | F26: 1 | G26: MN61RP7.ZsCampo
C27: SLOT 03 1734-IB8/C : 08 DI
C28: IO | D28: Local | E28: Min | F28: Max | G28: TAG 's | H28: DESCRIÇÃO
C29: DI.0 | E29: 0 | F29: 1 | G29: MN61RP8.ZsCampo
C30: DI.1 | E30: 0 | F30: 1 | G30: MN61RP12.ZsCampo
C31: DI.2 | E31: 0 | F31: 1 | G31: MX61RP12.ZsCampo
C32: DI.3 | E32: 0 | F32: 1 | G32: MN62RP9.ZsCampo
C33: DI.4 | E33: 0 | F33: 1 | G33: MX62RP9.ZsCampo
C34: DI.5 | E34: 0 | F34: 1 | G34: MN62RP10.ZsCampo
C35: DI.6 | E35: 0 | F35: 1 | G35: MX62RP10.ZsCampo
C36: DI.7 | E36: 0 | F36: 1 | G36: M60TR1.auto_on
C37: SLOT 04 1734-IB8/C : 08 DI
C38: IO | D38: Local | E38: Min | F38: Max | G38: TAG 's | H38: DESCRIÇÃO
C39: DI.0 | E39: 0 | F39: 1 | G39: SX60TR1B.ZsCampo
C40: DI.1 | E40: 0 | F40: 1 | G40: M60TR2.auto_on
C41: DI.2 | E41: 0 | F41: 1 | G41: SX60TR2B.ZsCampo
...

Sheet Rem6
C1: Milhão Ingredients Unidade - Rio Verde
C2: CPU CONTROLOGIX 1756-L73 192.100.3.1
C3: LISTA DE IO
G4: RESPONSAVEL TÉCNICO: Tallison Barros;
C6: 1734-AENTR/c Rem6 192.100.3.165
C7: SLOT 01 1734-IB8/C : 08 DI
C8: IO | D8: Local | E8: Min | F8: Max | G8: TAG 's | H8: DESCRIÇÃO
C9: DI.0 | E9: 0 | F9: 1 | G9: MN42MD1.ZsCampo
C10: DI.1 | E10: 0 | F10: 1 | G10: V63VP1.fb_esquerda
C11: DI.2 | E11: 0 | F11: 1 | G11: V63VP2.fb_direita
C12: DI.3 | E12: 0 | F12: 1 | G12: V63VP2.fb_esquerda
C13: DI.4 | E13: 0 | F13: 1 | G13: V63VP3.fb_direita
C14: DI.5 | E14: 0 | F14: 1 | G14: V63VP3.fb_esquerda
C15: DI.6 | E15: 0 | F15: 1 | G15: V63VP4.fb_direita
C16: DI.7 | E16: 0 | F16: 1 | G16: V63VP4.fb_esquerda
C17: SLOT 02 1734-IB8/C : 08 DI
C18: IO | D18: Local | E18: Min | F18: Max | G18: TAG 's | H18: DESCRIÇÃO
C19: DI.0 | E19: 0 | F19: 1 | G19: V63VP5.fb_direita
C20: DI.1 | E20: 0 | F20: 1 | G20: V63VP5.fb_esquerda
C21: DI.2 | E21: 0 | F21: 1 | G21: V63VP6.fb_direita
C22: DI.3 | E22: 0 | F22: 1 | G22: V63VP6.fb_esquerda
C23: DI.4 | E23: 0 | F23: 1 | G23: V63VP7.fb_direita
C24: DI.5 | E24: 0 | F24: 1 | G24: V63VP7.fb_esquerda
C25: DI.6 | E25: 0 | F25: 1 | G25: V63VP8.fb_direita
C26: DI.7 | E26: 0 | F26: 1 | G26: V63VP8.fb_esquerda
C27: SLOT 03 1734-IB8/C : 08 DI
C28: IO | D28: Local | E28: Min | F28: Max | G28: TAG 's | H28: DESCRIÇÃO
C29: DI.0 | E29: 0 | F29: 1 | G29: V63VP17.fb_direita
C30: DI.1 | E30: 0 | F30: 1 | G30: V63VP17.fb_esquerda
C31: DI.2 | E31: 0 | F31: 1 | G31: V63VP18.fb_direita
C32: DI.3 | E32: 0 | F32: 1 | G32: V63VP18.fb_esquerda
C33: DI.4 | E33: 0 | F33: 1 | G33: RUN63FT20.ZsCampo
C34: DI.5 | E34: 0 | F34: 1 | G34: ALA63FT20.ZsCampo
C35: DI.6 | E35: 0 | F35: 1 | G35: V65VP10.fb_direita
C36: DI.7 | E36: 0 | F36: 1 | G36: V65VP10.fb_esquerda
C37: SLOT 04 1734-IB8/C : 08 DI
C38: IO | D38: Local | E38: Min | F38: Max | G38: TAG 's | H38: DESCRIÇÃO
C39: DI.0 | E39: 0 | F39: 1 | G39: V65VP11.fb_direita
C40: DI.1 | E40: 0 | F40: 1 | G40: V65VP11.fb_esquerda
C41: DI.2 | E41: 0 | F41: 1 | G41: V65VP12.fb_direita
...

Sheet Rem7
C1: Milhão Ingredients Unidade - Rio Verde
C2: CPU CONTROLOGIX 1756-L73 192.100.3.1
C3: LISTA DE IO
G4: RESPONSAVEL TÉCNICO: Tallison Barros;
C6: 1734-AENTR/c Rem7 192.100.3.166
C7: SLOT 01 1734-IB8/C : 08 DI
C8: IO | D8: Local | E8: Min | F8: Max | G8: TAG 's | H8: DESCRIÇÃO
C9: DI.0 | E9: 0 | F9: 1 | G9: MX620I.ZsCampo
C10: DI.1 | E10: 0 | F10: 1 | G10: MX621I.ZsCampo
C11: DI.2 | E11: 0 | F11: 1 | G11: MX622I.ZsCampo
C12: DI.3 | E12: 0 | F12: 1 | G12: MX623I.ZsCampo
C13: DI.4 | E13: 0 | F13: 1 | G13: MX624I.ZsCampo
C14: DI.5 | E14: 0 | F14: 1 | G14: MX613I.ZsCampo
C15: DI.6 | E15: 0 | F15: 1 | G15: MX614I.ZsCampo
C16: DI.7 | E16: 0 | F16: 1 | G16: MX615I.ZsCampo
C17: SLOT 02 1734-IB8/C : 08 DI
C18: IO | D18: Local | E18: Min | F18: Max | G18: TAG 's | H18: DESCRIÇÃO
C19: DI.0 | E19: 0 | F19: 1 | G19: MX616I.ZsCampo
C20: DI.1 | E20: 0 | F20: 1 | G20: MX617I.ZsCampo
C21: DI.2 | E21: 0 | F21: 1 | G21: MX618I.ZsCampo
C22: DI.3 | E22: 0 | F22: 1 | G22: MX619I.ZsCampo
C23: DI.4 | E23: 0 | F23: 1 | G23: MN620I.ZsCampo
C24: DI.5 | E24: 0 | F24: 1 | G24: MN621I.ZsCampo
C25: DI.6 | E25: 0 | F25: 1 | G25: MN622I.ZsCampo
C26: DI.7 | E26: 0 | F26: 1 | G26: MN623I.ZsCampo
C27: SLOT 03 1734-IB8/C : 08 DI
C28: IO | D28: Local | E28: Min | F28: Max | G28: TAG 's | H28: DESCRIÇÃO
C29: DI.0 | E29: 0 | F29: 1 | G29: MN624I.ZsCampo
C30: DI.1 | E30: 0 | F30: 1 | G30: MN613I.ZsCampo
C31: DI.2 | E31: 0 | F31: 1 | G31: MN614I.ZsCampo
C32: DI.3 | E32: 0 | F32: 1 | G32: MN615I.ZsCampo
C33: DI.4 | E33: 0 | F33: 1 | G33: MN616I.ZsCampo
C34: DI.5 | E34: 0 | F34: 1 | G34: MN617I.ZsCampo
C35: DI.6 | E35: 0 | F35: 1 | G35: MN618I.ZsCampo
C36: DI.7 | E36: 0 | F36: 1 | G36: MN619I.ZsCampo
C37: SLOT 04 1734-IB8/C : 08 DI
C38: IO | D38: Local | E38: Min | F38: Max | G38: TAG 's | H38: DESCRIÇÃO
C39: DI.0 | E39: 0 | F39: 1 | G39: V68VP19.fb_direita
C40: DI.1 | E40: 0 | F40: 1 | G40: V68VP19.fb_esquerda
C41: DI.2 | E41: 0 | F41: 1 | G41: V68VP20.fb_direita
...
